<?xml version="1.0"?>
<robot xmlns:xacro="http://www.ros.org/wiki/xacro">

  <!-- Definir a roda esquerda -->
  <link name="left_wheel">
    <visual>
      <geometry>
        <cylinder radius="0.2" length="0.05"/>
      </geometry>
      <origin xyz="0 0 0" rpy="1.5708 0 0"/> <!-- Rotaciona 90 graus em torno do eixo X -->
      <material name="gray"/>
    </visual>
    <collision>
      <geometry>
        <cylinder radius="0.2" length="0.05"/>
      </geometry>
      <origin xyz="0 0 0" rpy="1.5708 0 0"/> <!-- Rotaciona 90 graus em torno do eixo X -->
    </collision>
    <inertial>
      <mass value="0.5"/>
      <origin xyz="0 0 0"/>
      <inertia ixx="0.01" ixy="0" ixz="0" iyy="0.01" iyz="0" izz="0.01"/>
    </inertial>
  </link>

  <!-- Definir a roda direita -->
  <link name="right_wheel">
    <visual>
      <geometry>
        <cylinder radius="0.2" length="0.05"/>
      </geometry>
      <origin xyz="0 0 0" rpy="1.5708 0 0"/>
      <material name="gray"/>
    </visual>
    <collision>
      <geometry>
        <cylinder radius="0.2" length="0.05"/>
      </geometry>
      <origin xyz="0 0 0" rpy="1.5708 0 0"/>
    </collision>
    <inertial>
      <mass value="0.5"/>
      <origin xyz="0 0 0"/>
      <inertia ixx="0.01" ixy="0" ixz="0" iyy="0.01" iyz="0" izz="0.01"/>
    </inertial>
  </link>

  <!-- Definir as juntas (joints) para as rodas -->
  <joint name="left_wheel_joint" type="continuous">
    <parent link="base_link"/>
    <child link="left_wheel"/>
    <origin xyz="0 0.275 0" rpy="0 0 0"/>
    <axis xyz="0 0 1"/>
    <limit effort="100" velocity="10"/>
  </joint>

  <joint name="right_wheel_joint" type="continuous">
    <parent link="base_link"/>
    <child link="right_wheel"/>
    <origin xyz="0 -0.275 0" rpy="0 0 0"/>
    <axis xyz="0 0 1"/>
    <limit effort="100" velocity="10"/>
  </joint>

</robot>
